<sdf version='1.7'>
  <world name='default'>
    <light name='sun' type='directional'>
      <cast_shadows>1</cast_shadows>
      <pose>0 0 10 0 -0 0</pose>
      <diffuse>0.8 0.8 0.8 1</diffuse>
      <specular>0.2 0.2 0.2 1</specular>
      <attenuation>
        <range>1000</range>
        <constant>0.9</constant>
        <linear>0.01</linear>
        <quadratic>0.001</quadratic>
      </attenuation>
      <direction>-0.5 0.1 -0.9</direction>
      <spot>
        <inner_angle>0</inner_angle>
        <outer_angle>0</outer_angle>
        <falloff>0</falloff>
      </spot>
    </light>
    <model name='ground_plane'>
      <static>1</static>
      <link name='link'>
        <collision name='collision'>
          <geometry>
            <plane>
              <normal>0 0 1</normal>
              <size>100 100</size>
            </plane>
          </geometry>
          <surface>
            <contact>
              <collide_bitmask>65535</collide_bitmask>
              <ode/>
            </contact>
            <friction>
              <ode>
                <mu>100</mu>
                <mu2>50</mu2>
              </ode>
              <torsional>
                <ode/>
              </torsional>
            </friction>
            <bounce/>
          </surface>
          <max_contacts>10</max_contacts>
        </collision>
        <visual name='visual'>
          <cast_shadows>0</cast_shadows>
          <geometry>
            <plane>
              <normal>0 0 1</normal>
              <size>100 100</size>
            </plane>
          </geometry>
          <material>
            <script>
              <uri>file://media/materials/scripts/gazebo.material</uri>
              <name>Gazebo/Grey</name>
            </script>
          </material>
        </visual>
        <self_collide>0</self_collide>
        <enable_wind>0</enable_wind>
        <kinematic>0</kinematic>
      </link>
    </model>
    <gravity>0 0 -9.8</gravity>
    <magnetic_field>6e-06 2.3e-05 -4.2e-05</magnetic_field>
    <atmosphere type='adiabatic'/>
    <physics type='ode'>
      <max_step_size>0.001</max_step_size>
      <real_time_factor>1</real_time_factor>
      <real_time_update_rate>1000</real_time_update_rate>
    </physics>
    <scene>
      <ambient>0.4 0.4 0.4 1</ambient>
      <background>0.7 0.7 0.7 1</background>
      <shadows>1</shadows>
    </scene>
    <wind/>
    <spherical_coordinates>
      <surface_model>EARTH_WGS84</surface_model>
      <latitude_deg>0</latitude_deg>
      <longitude_deg>0</longitude_deg>
      <elevation>0</elevation>
      <heading_deg>0</heading_deg>
    </spherical_coordinates>
    
    <model name='test2_pkg'>
      <link name='base_link'>
        <inertial>
          <pose>0.075 -0 -0.0025 0 -0 0</pose>
          <mass>0.0581718</mass>
          <inertia>
            <ixx>3.12909e-06</ixx>
            <ixy>-2.32521e-20</ixy>
            <ixz>2.57678e-24</ixz>
            <iyy>0.000135512</iyy>
            <iyz>-8.01283e-24</iyz>
            <izz>0.000138398</izz>
          </inertia>
        </inertial>
        <collision name='base_link_collision'>
          <pose>0 0 0 0 -0 0</pose>
          <geometry>
            <mesh>
              <scale>1 1 1</scale>
              <uri>/home/vulcan/Acdimic/urdf_ws/src/pipe_robot/test2_pkg/meshes/base_link.STL</uri>
            </mesh>
          </geometry>
          <max_contacts>10</max_contacts>
          <surface>
            <contact>
              <ode/>
            </contact>
            <bounce/>
            <friction>
              <torsional>
                <ode/>
              </torsional>
              <ode/>
            </friction>
          </surface>
        </collision>
        <visual name='base_link_visual'>
          <pose>0 0 0 0 -0 0</pose>
          <geometry>
            <mesh>
              <scale>1 1 1</scale>
              <uri>/home/vulcan/Acdimic/urdf_ws/src/pipe_robot/test2_pkg/meshes/base_link.STL</uri>
            </mesh>
          </geometry>
        </visual>
        <self_collide>0</self_collide>
        <enable_wind>0</enable_wind>
        <kinematic>0</kinematic>
      </link>
      <joint name='force1' type='revolute'>
        <pose relative_to='base_link'>0 0 0 0 -0 0</pose>
        <parent>base_link</parent>
        <child>link1</child>
        <axis>
          <xyz>0 0 1</xyz>
          <limit>
            <lower>-1e+16</lower>
            <upper>1e+16</upper>
          </limit>
          <dynamics>
            <spring_reference>0</spring_reference>
            <spring_stiffness>0</spring_stiffness>
          </dynamics>
        </axis>
      </joint>
      <link name='link1'>
        <pose relative_to='force1'>0 0 0 0 -0 0</pose>
        <inertial>
          <pose>0.005545 0.019216 0.0025 0 -0 0</pose>
          <mass>0.0195343</mass>
          <inertia>
            <ixx>5.46617e-06</ixx>
            <ixy>-1.27834e-06</ixy>
            <ixz>-1.03615e-23</ixz>
            <iyy>1.40511e-06</iyy>
            <iyz>-4.66129e-23</iyz>
            <izz>6.78988e-06</izz>
          </inertia>
        </inertial>
        <collision name='link1_collision'>
          <pose>0 0 0 0 -0 0</pose>
          <geometry>
            <mesh>
              <scale>1 1 1</scale>
              <uri>/home/vulcan/Acdimic/urdf_ws/src/pipe_robot/test2_pkg/meshes/link1.STL</uri>
            </mesh>
          </geometry>
          <max_contacts>10</max_contacts>
          <surface>
            <contact>
              <ode/>
            </contact>
            <bounce/>
            <friction>
              <torsional>
                <ode/>
              </torsional>
              <ode/>
            </friction>
          </surface>
        </collision>
        <visual name='link1_visual'>
          <pose>0 0 0 0 -0 0</pose>
          <geometry>
            <mesh>
              <scale>1 1 1</scale>
              <uri>/home/vulcan/Acdimic/urdf_ws/src/pipe_robot/test2_pkg/meshes/link1.STL</uri>
            </mesh>
          </geometry>
        </visual>
        <self_collide>0</self_collide>
        <enable_wind>0</enable_wind>
        <kinematic>0</kinematic>
      </link>
      <joint name='no_force1' type='revolute'>
        <pose relative_to='link1'>0.01109 0.038432 0 0 -0 0</pose>
        <parent>link1</parent>
        <child>link2</child>
        <axis>
          <xyz>0 0 1</xyz>
          <limit>
            <lower>-1e+16</lower>
            <upper>1e+16</upper>
          </limit>
          <dynamics>
            <spring_reference>0</spring_reference>
            <spring_stiffness>0</spring_stiffness>
          </dynamics>
        </axis>
      </joint>
      <link name='link2'>
        <pose relative_to='no_force1'>0 0 0 0 -0 0</pose>
        <inertial>
          <pose>0.035828 0.017787 -0.0025 0 -0 0</pose>
          <mass>0.0335843</mass>
          <inertia>
            <ixx>6.78513e-06</ixx>
            <ixy>-1.00469e-05</ixy>
            <ixz>4.26661e-23</ixz>
            <iyy>2.20345e-05</iyy>
            <iyz>-3.05257e-23</iyz>
            <izz>2.86797e-05</izz>
          </inertia>
        </inertial>
        <collision name='link2_collision'>
          <pose>0 0 0 0 -0 0</pose>
          <geometry>
            <mesh>
              <scale>1 1 1</scale>
              <uri>/home/vulcan/Acdimic/urdf_ws/src/pipe_robot/test2_pkg/meshes/link2.STL</uri>
            </mesh>
          </geometry>
          <max_contacts>10</max_contacts>
          <surface>
            <contact>
              <ode/>
            </contact>
            <bounce/>
            <friction>
              <torsional>
                <ode/>
              </torsional>
              <ode/>
            </friction>
          </surface>
        </collision>
        <visual name='link2_visual'>
          <pose>0 0 0 0 -0 0</pose>
          <geometry>
            <mesh>
              <scale>1 1 1</scale>
              <uri>/home/vulcan/Acdimic/urdf_ws/src/pipe_robot/test2_pkg/meshes/link2.STL</uri>
            </mesh>
          </geometry>
        </visual>
        <self_collide>0</self_collide>
        <enable_wind>0</enable_wind>
        <kinematic>0</kinematic>
      </link>
      <joint name='no_force2' type='revolute'>
        <pose relative_to='link2'>0.071655 0.035574 0 0 -0 0</pose>
        <parent>link2</parent>
        <child>link3</child>
        <axis>
          <xyz>0 0 1</xyz>
          <limit>
            <lower>-1e+16</lower>
            <upper>1e+16</upper>
          </limit>
          <dynamics>
            <spring_reference>0</spring_reference>
            <spring_stiffness>0</spring_stiffness>
          </dynamics>
        </axis>
      </joint>
      <link name='link3'>
        <pose relative_to='no_force2'>0 0 0 0 -0 0</pose>
        <inertial>
          <pose>0.033627 -0.037003 -0.0075 0 -0 0</pose>
          <mass>0.0406093</mass>
          <inertia>
            <ixx>2.67201e-05</ixx>
            <ixy>2.23034e-05</ixy>
            <ixz>-6.8679e-24</ixz>
            <iyy>2.24465e-05</iyy>
            <iyz>3.27291e-23</iyz>
            <izz>4.89974e-05</izz>
          </inertia>
        </inertial>
        <collision name='link3_collision'>
          <pose>0 0 0 0 -0 0</pose>
          <geometry>
            <mesh>
              <scale>1 1 1</scale>
              <uri>/home/vulcan/Acdimic/urdf_ws/src/pipe_robot/test2_pkg/meshes/link3.STL</uri>
            </mesh>
          </geometry>
          <max_contacts>10</max_contacts>
          <surface>
            <contact>
              <ode/>
            </contact>
            <bounce/>
            <friction>
              <torsional>
                <ode/>
              </torsional>
              <ode/>
            </friction>
          </surface>
        </collision>
        <visual name='link3_visual'>
          <pose>0 0 0 0 -0 0</pose>
          <geometry>
            <mesh>
              <scale>1 1 1</scale>
              <uri>/home/vulcan/Acdimic/urdf_ws/src/pipe_robot/test2_pkg/meshes/link3.STL</uri>
            </mesh>
          </geometry>
        </visual>
        <self_collide>0</self_collide>
        <enable_wind>0</enable_wind>
        <kinematic>0</kinematic>
      </link>
      <joint name='no_force3' type='revolute'>
        <pose relative_to='link3'>0.067254 -0.074006 0 0 -0 0</pose>
        <parent>link3</parent>
        <child>link4</child>
        <axis>
          <xyz>0 0 1</xyz>
          <limit>
            <lower>-1e+16</lower>
            <upper>1e+16</upper>
          </limit>
          <dynamics>
            <spring_reference>0</spring_reference>
            <spring_stiffness>0</spring_stiffness>
          </dynamics>
        </axis>
      </joint>
      <link name='link4'>
        <pose relative_to='no_force3'>0 0 0 0 -0 0</pose>
        <inertial>
          <pose>-0.075 -0 -0.0025 0 -0 0</pose>
          <mass>0.0581718</mass>
          <inertia>
            <ixx>3.12909e-06</ixx>
            <ixy>-2.32521e-20</ixy>
            <ixz>2.2699e-24</ixz>
            <iyy>0.000135512</iyy>
            <iyz>-7.74793e-24</iyz>
            <izz>0.000138398</izz>
          </inertia>
        </inertial>
        <collision name='link4_collision'>
          <pose>0 0 0 0 -0 0</pose>
          <geometry>
            <mesh>
              <scale>1 1 1</scale>
              <uri>/home/vulcan/Acdimic/urdf_ws/src/pipe_robot/test2_pkg/meshes/link4.STL</uri>
            </mesh>
          </geometry>
          <max_contacts>10</max_contacts>
          <surface>
            <contact>
              <ode/>
            </contact>
            <bounce/>
            <friction>
              <torsional>
                <ode/>
              </torsional>
              <ode/>
            </friction>
          </surface>
        </collision>
        <visual name='link4_visual'>
          <pose>0 0 0 0 -0 0</pose>
          <geometry>
            <mesh>
              <scale>1 1 1</scale>
              <uri>/home/vulcan/Acdimic/urdf_ws/src/pipe_robot/test2_pkg/meshes/link4.STL</uri>
            </mesh>
          </geometry>
        </visual>
        <self_collide>0</self_collide>
        <enable_wind>0</enable_wind>
        <kinematic>0</kinematic>
      </link>
      <pose>0 0 0 0 -0 0</pose>
    </model>
    <state world_name='default'>
      <sim_time>20 749000000</sim_time>
      <real_time>20 869457295</real_time>
      <wall_time>1764741425 105577863</wall_time>
      <iterations>20749</iterations>
      <model name='ground_plane'>
        <pose>0 0 0 0 -0 0</pose>
        <scale>1 1 1</scale>
        <link name='link'>
          <pose>0 0 0 0 -0 0</pose>
          <velocity>0 0 0 0 -0 0</velocity>
          <acceleration>0 0 0 0 -0 0</acceleration>
          <wrench>0 0 0 0 -0 0</wrench>
        </link>
      </model>
      <model name='test2_pkg'>
        <pose>0.006237 -0.008019 0.005565 0.045742 -1.1e-05 -0.860352</pose>
        <scale>1 1 1</scale>
        <link name='base_link'>
          <pose>0.006237 -0.008019 0.005565 0.045742 -1.1e-05 -0.860352</pose>
          <velocity>-0.000596 4e-06 -9.4e-05 0.018151 -0.1323 -0.001169</velocity>
          <acceleration>-0.430237 0.038304 10.7188 1.84923 -1.36566 -2.60598</acceleration>
          <wrench>-0.025028 0.002228 0.623533 0 -0 0</wrench>
        </link>
        <link name='link1'>
          <pose>0.00624 -0.00802 0.005569 0.027959 -0.036498 0.049905</pose>
          <velocity>6e-06 -0.000263 0.000608 0.003266 -0.199493 -0.023531</velocity>
          <acceleration>-0.734628 -0.746856 3.11953 1.55737 -0.991279 0.207427</acceleration>
          <wrench>-0.01435 -0.014589 0.060938 0 -0 0</wrench>
        </link>
        <link name='link2'>
          <pose>0.015352 0.030902 0.007046 0.031109 -0.033642 -0.030899</pose>
          <velocity>0.000457 -0.000112 0.0025 0.067761 -0.08296 -0.012217</velocity>
          <acceleration>0.514736 -0.621469 13.3036 -2.96194 -0.485679 -2.07676</acceleration>
          <wrench>0.017287 -0.020872 0.446791 0 -0 0</wrench>
        </link>
        <link name='link3'>
          <pose>0.087991 0.06423 0.010564 0.03091 -0.033954 -0.006605</pose>
          <velocity>-0.00033 -0.001826 0.011084 0.179011 -0.024869 0.010719</velocity>
          <acceleration>-0.435232 0.529356 10.606 1.42491 1.05509 3.01953</acceleration>
          <wrench>-0.017674 0.021497 0.430703 0 -0 0</wrench>
        </link>
        <link name='link4'>
          <pose>0.154795 -0.010184 0.01056 0.031226 -0.03333 -0.021641</pose>
          <velocity>0.000605 -0.001177 -0.000521 0.085664 0.056337 -0.001716</velocity>
          <acceleration>-0.169816 -0.340736 7.68565 -2.9713 -1.43384 1.52088</acceleration>
          <wrench>-0.009879 -0.019821 0.447088 0 -0 0</wrench>
        </link>
      </model>
      <light name='sun'>
        <pose>0 0 10 0 -0 0</pose>
      </light>
    </state>
    <gui fullscreen='0'>
      <camera name='user_camera'>
        <pose>5 -5 2 0 0.275643 2.35619</pose>
        <view_controller>orbit</view_controller>
        <projection_type>perspective</projection_type>
      </camera>
    </gui>
  </world>
</sdf>
